<?xml version="1.0"?>
<robot name="linkage">
  <!-- Link A -->
  <link name="link_A">
    <inertial>
      <origin xyz="0 0 0"/>
      <mass value="0.5"/>
      <inertia ixx="0.005" iyy="0.005" izz="0.005" ixy="0" ixz="0" iyz="0"/>
    </inertial>
    <visual>
      <origin xyz="0 0 0"/>
      <geometry>
        <box size="0.5 0.5 0.1"/>
      </geometry>
      <material name="red">
        <color rgba="1 0 0 1"/>
      </material>
    </visual>
    <collision>
      <origin xyz="0 0 0"/>
      <geometry>
        <box size="0.5 0.5 0.1"/>
      </geometry>
    </collision>
  </link>

  <!-- Link B -->
  <link name="link_B">
    <inertial>
      <origin xyz="0 0 -0.5"/>
      <mass value="0.5"/>
      <inertia ixx="0.005" iyy="0.005" izz="0.005" ixy="0" ixz="0" iyz="0"/>
    </inertial>
    <visual>
      <origin xyz="0 0 -0.5"/>
      <geometry>
        <cylinder radius="0.05" length="1"/>
      </geometry>
      <material name="blue">
        <color rgba="0 0 1 1"/>
      </material>
    </visual>
    <collision>
      <origin xyz="0 0 -0.5"/>
      <geometry>
        <cylinder radius="0.05" length="1"/>
      </geometry>
    </collision>
  </link>

  <!-- Link C -->
  <link name="link_C">
    <inertial>
      <origin xyz="0 0 -0.5"/>
      <mass value="0.5"/>
      <inertia ixx="0.005" iyy="0.005" izz="0.005" ixy="0" ixz="0" iyz="0"/>
    </inertial>
    <visual>
      <origin xyz="0 0 -0.5"/>
      <geometry>
        <cylinder radius="0.05" length="1"/>
      </geometry>
      <material name="green">
        <color rgba="0 1 0 1"/>
      </material>
    </visual>
    <collision>
      <origin xyz="0 0 -0.5"/>
      <geometry>
        <cylinder radius="0.05" length="1"/>
      </geometry>
    </collision>
  </link>

  <!-- Link D (per il giunto prismatico) -->
  <link name="link_D">
    <inertial>
      <origin xyz="0 0 0"/>
      <mass value="0.5"/>
      <inertia ixx="0.005" iyy="0.005" izz="0.005" ixy="0" ixz="0" iyz="0"/>
    </inertial>
    <visual>
      <origin xyz="0 0 0"/>
      <geometry>
        <cylinder radius="0.04" length="0.5"/>
      </geometry>
      <material name="yellow">
        <color rgba="1 1 0 1"/>
      </material>
    </visual>
    <collision>
      <origin xyz="0 0 0"/>
      <geometry>
        <cylinder radius="0.04" length="0.5"/>
      </geometry>
    </collision>
  </link>

  <!-- Joint A: Collega link_A a link_B (revolute) -->
  <joint name="joint_A" type="revolute">
    <parent link="link_A"/>
    <child link="link_B"/>
    <origin xyz="0 0 -0.05" rpy="0 0 0"/>
    <axis xyz="0 1 0"/>
    <limit lower="-1.57" upper="1.57" effort="10" velocity="1.0"/>
  </joint>

  <!-- Joint B: Collega link_B a link_C (revolute) -->
  <joint name="joint_B" type="revolute">
    <parent link="link_B"/>
    <child link="link_C"/>
    <origin xyz="0 0 -1" rpy="0 0 0"/>
    <axis xyz="1 0 0"/>
    <limit lower="-1.57" upper="1.57" effort="10" velocity="1.0"/>
  </joint>

  <!-- Joint C: Collega link_C a link_D (prismatic) -->
  <joint name="joint_C" type="prismatic">
    <parent link="link_C"/>
    <child link="link_D"/>
    <origin xyz="0 0 -1" rpy="0 0 0"/>
    <axis xyz="0 0 1"/>
    <limit lower="0.0" upper="0.5" effort="10" velocity="0.5"/>
  </joint>
</robot>
